Workbook
Name NamedRange1: Midterms!$H:$H

Sheet Grading
A1: 0 | B1: 5
A2: 1 | B2: 4.9
A3: 2 | B3: 4.9
A4: 3 | B4: 4.9
A5: 4 | B5: 4.8
A6: 5 | B6: 4.8
A7: 6 | B7: 4.7
A8: 7 | B8: 4.7
A9: 8 | B9: 4.6
A10: 9 | B10: 4.6
A11: 10 | B11: 4.5
A12: 11 | B12: 4.5
... A101: 100 | B101: 1

Sheet Midterms
A1: IPT101A SECTION D
A2: STUDENTS | AH2: Midterm Exam
AA3: CA TOTAL | AB3: % | AC3: CA GRADE | AD3: Quiz1 | AE3: QUIZ TOTAL | AF3: % | AG3: QUIZ GRADE | AH3: Exam | AI3: % | AJ3: Midterm Exam Grade | AK3: Midterm Grade
A4: DATE
A5: TOTAL POINTS | AA5: =SUM(S5:Z5) -> 0 | AB5: 100 | AC5: =VLOOKUP(AB5,Grading!A1:B101,2,TRUE) -> 1 | AD5: 100 | AE5: =SUM(AD5) -> 100 | AF5: 100 | AG5: =VLOOKUP(AF5,Grading!A1:B101,2,TRUE) -> 1 | AH5: 100 | AI5: 100 | AJ5: =VLOOKUP(AI5,Grading!A1:B101,2,TRUE) -> 1 | AK5: =ROUNDDOWN((AC5*0.2)+(AG5*0.2)+(AJ5*0.6),1) -> 1
A6: {=_xlfn.SEQUENCE(42,1)} -> 1 | AA6: =SUM(S6:Z6) -> 0 | AB6: =ROUNDUP(AA6*100/$AA$5,0) -> #DIV/0! | AC6: =VLOOKUP(AB6,Grading!$A$1:$B$102,2,TRUE) -> #DIV/0! | AE6: =SUM(AD6) -> 0 | AF6: =ROUNDUP(AE6*100/$AE$5,0) -> 0 | AG6: =VLOOKUP(AF6,Grading!$A$1:$B$102,2,TRUE) -> 5 | AI6: =ROUNDUP(AH6*100/$AH$5,0) -> 0 | AJ6: =VLOOKUP(AI6,Grading!$A$1:$B$102,2,TRUE) -> 5 | AK6: =ROUNDDOWN((AC6*0.2)+(AG6*0.2)+(AJ6*0.6),1) -> #DIV/0! | AL6: =IF(AK6<=3,"PASS","FAIL") -> #DIV/0!
A7: 2 | AA7: =SUM(S7:Z7) -> 0 | AB7: =ROUNDUP(AA7*100/$AA$5,0) -> #DIV/0! | AC7: =VLOOKUP(AB7,Grading!$A$1:$B$102,2,TRUE) -> #DIV/0! | AE7: =SUM(AD7) -> 0 | AF7: =ROUNDUP(AE7*100/$AE$5,0) -> 0 | AG7: =VLOOKUP(AF7,Grading!$A$1:$B$102,2,TRUE) -> 5 | AI7: =ROUNDUP(AH7*100/$AH$5,0) -> 0 | AJ7: =VLOOKUP(AI7,Grading!$A$1:$B$102,2,TRUE) -> 5 | AK7: =ROUNDDOWN((AC7*0.2)+(AG7*0.2)+(AJ7*0.6),1) -> #DIV/0! | AL7: =IF(AK7<=3,"PASS","FAIL") -> #DIV/0!
A8: 3 | AA8: =SUM(S8:Z8) -> 0 | AB8: =ROUNDUP(AA8*100/$AA$5,0) -> #DIV/0! | AC8: =VLOOKUP(AB8,Grading!$A$1:$B$102,2,TRUE) -> #DIV/0! | AE8: =SUM(AD8) -> 0 | AF8: =ROUNDUP(AE8*100/$AE$5,0) -> 0 | AG8: =VLOOKUP(AF8,Grading!$A$1:$B$102,2,TRUE) -> 5 | AI8: =ROUNDUP(AH8*100/$AH$5,0) -> 0 | AJ8: =VLOOKUP(AI8,Grading!$A$1:$B$102,2,TRUE) -> 5 | AK8: =ROUNDDOWN((AC8*0.2)+(AG8*0.2)+(AJ8*0.6),1) -> #DIV/0! | AL8: =IF(AK8<=3,"PASS","FAIL") -> #DIV/0!
A9: 4 | AA9: =SUM(S9:Z9) -> 0 | AB9: =ROUNDUP(AA9*100/$AA$5,0) -> #DIV/0! | AC9: =VLOOKUP(AB9,Grading!$A$1:$B$102,2,TRUE) -> #DIV/0! | AE9: =SUM(AD9) -> 0 | AF9: =ROUNDUP(AE9*100/$AE$5,0) -> 0 | AG9: =VLOOKUP(AF9,Grading!$A$1:$B$102,2,TRUE) -> 5 | AI9: =ROUNDUP(AH9*100/$AH$5,0) -> 0 | AJ9: =VLOOKUP(AI9,Grading!$A$1:$B$102,2,TRUE) -> 5 | AK9: =ROUNDDOWN((AC9*0.2)+(AG9*0.2)+(AJ9*0.6),1) -> #DIV/0! | AL9: =IF(AK9<=3,"PASS","FAIL") -> #DIV/0!
A10: 5 | AA10: =SUM(S10:Z10) -> 0 | AB10: =ROUNDUP(AA10*100/$AA$5,0) -> #DIV/0! | AC10: =VLOOKUP(AB10,Grading!$A$1:$B$102,2,TRUE) -> #DIV/0! | AE10: =SUM(AD10) -> 0 | AF10: =ROUNDUP(AE10*100/$AE$5,0) -> 0 | AG10: =VLOOKUP(AF10,Grading!$A$1:$B$102,2,TRUE) -> 5 | AI10: =ROUNDUP(AH10*100/$AH$5,0) -> 0 | AJ10: =VLOOKUP(AI10,Grading!$A$1:$B$102,2,TRUE) -> 5 | AK10: =ROUNDDOWN((AC10*0.2)+(AG10*0.2)+(AJ10*0.6),1) -> #DIV/0! | AL10: =IF(AK10<=3,"PASS","FAIL") -> #DIV/0!
A11: 6 | AA11: =SUM(S11:Z11) -> 0 | AB11: =ROUNDUP(AA11*100/$AA$5,0) -> #DIV/0! | AC11: =VLOOKUP(AB11,Grading!$A$1:$B$102,2,TRUE) -> #DIV/0! | AE11: =SUM(AD11) -> 0 | AF11: =ROUNDUP(AE11*100/$AE$5,0) -> 0 | AG11: =VLOOKUP(AF11,Grading!$A$1:$B$102,2,TRUE) -> 5 | AI11: =ROUNDUP(AH11*100/$AH$5,0) -> 0 | AJ11: =VLOOKUP(AI11,Grading!$A$1:$B$102,2,TRUE) -> 5 | AK11: =ROUNDDOWN((AC11*0.2)+(AG11*0.2)+(AJ11*0.6),1) -> #DIV/0! | AL11: =IF(AK11<=3,"PASS","FAIL") -> #DIV/0!
A12: 7 | AA12: =SUM(S12:Z12) -> 0 | AB12: =ROUNDUP(AA12*100/$AA$5,0) -> #DIV/0! | AC12: =VLOOKUP(AB12,Grading!$A$1:$B$102,2,TRUE) -> #DIV/0! | AE12: =SUM(AD12) -> 0 | AF12: =ROUNDUP(AE12*100/$AE$5,0) -> 0 | AG12: =VLOOKUP(AF12,Grading!$A$1:$B$102,2,TRUE) -> 5 | AI12: =ROUNDUP(AH12*100/$AH$5,0) -> 0 | AJ12: =VLOOKUP(AI12,Grading!$A$1:$B$102,2,TRUE) -> 5 | AK12: =ROUNDDOWN((AC12*0.2)+(AG12*0.2)+(AJ12*0.6),1) -> #DIV/0! | AL12: =IF(AK12<=3,"PASS","FAIL") -> #DIV/0!
A13: 8 | AA13: =SUM(S13:Z13) -> 0 | AB13: =ROUNDUP(AA13*100/$AA$5,0) -> #DIV/0! | AC13: =VLOOKUP(AB13,Grading!$A$1:$B$102,2,TRUE) -> #DIV/0! | AE13: =SUM(AD13) -> 0 | AF13: =ROUNDUP(AE13*100/$AE$5,0) -> 0 | AG13: =VLOOKUP(AF13,Grading!$A$1:$B$102,2,TRUE) -> 5 | AI13: =ROUNDUP(AH13*100/$AH$5,0) -> 0 | AJ13: =VLOOKUP(AI13,Grading!$A$1:$B$102,2,TRUE) -> 5 | AK13: =ROUNDDOWN((AC13*0.2)+(AG13*0.2)+(AJ13*0.6),1) -> #DIV/0! | AL13: =IF(AK13<=3,"PASS","FAIL") -> #DIV/0!
A14: 9 | AA14: =SUM(S14:Z14) -> 0 | AB14: =ROUNDUP(AA14*100/$AA$5,0) -> #DIV/0! | AC14: =VLOOKUP(AB14,Grading!$A$1:$B$102,2,TRUE) -> #DIV/0! | AE14: =SUM(AD14) -> 0 | AF14: =ROUNDUP(AE14*100/$AE$5,0) -> 0 | AG14: =VLOOKUP(AF14,Grading!$A$1:$B$102,2,TRUE) -> 5 | AI14: =ROUNDUP(AH14*100/$AH$5,0) -> 0 | AJ14: =VLOOKUP(AI14,Grading!$A$1:$B$102,2,TRUE) -> 5 | AK14: =ROUNDDOWN((AC14*0.2)+(AG14*0.2)+(AJ14*0.6),1) -> #DIV/0! | AL14: =IF(AK14<=3,"PASS","FAIL") -> #DIV/0!
A15: 10 | AA15: =SUM(S15:Z15) -> 0 | AB15: =ROUNDUP(AA15*100/$AA$5,0) -> #DIV/0! | AC15: =VLOOKUP(AB15,Grading!$A$1:$B$102,2,TRUE) -> #DIV/0! | AE15: =SUM(AD15) -> 0 | AF15: =ROUNDUP(AE15*100/$AE$5,0) -> 0 | AG15: =VLOOKUP(AF15,Grading!$A$1:$B$102,2,TRUE) -> 5 | AI15: =ROUNDUP(AH15*100/$AH$5,0) -> 0 | AJ15: =VLOOKUP(AI15,Grading!$A$1:$B$102,2,TRUE) -> 5 | AK15: =ROUNDDOWN((AC15*0.2)+(AG15*0.2)+(AJ15*0.6),1) -> #DIV/0! | AL15: =IF(AK15<=3,"PASS","FAIL") -> #DIV/0!
A16: 11 | AA16: =SUM(S16:Z16) -> 0 | AB16: =ROUNDUP(AA16*100/$AA$5,0) -> #DIV/0! | AC16: =VLOOKUP(AB16,Grading!$A$1:$B$102,2,TRUE) -> #DIV/0! | AE16: =SUM(AD16) -> 0 | AF16: =ROUNDUP(AE16*100/$AE$5,0) -> 0 | AG16: =VLOOKUP(AF16,Grading!$A$1:$B$102,2,TRUE) -> 5 | AI16: =ROUNDUP(AH16*100/$AH$5,0) -> 0 | AJ16: =VLOOKUP(AI16,Grading!$A$1:$B$102,2,TRUE) -> 5 | AK16: =ROUNDDOWN((AC16*0.2)+(AG16*0.2)+(AJ16*0.6),1) -> #DIV/0! | AL16: =IF(AK16<=3,"PASS","FAIL") -> #DIV/0!
A17: 12 | AA17: =SUM(S17:Z17) -> 0 | AB17: =ROUNDUP(AA17*100/$AA$5,0) -> #DIV/0! | AC17: =VLOOKUP(AB17,Grading!$A$1:$B$102,2,TRUE) -> #DIV/0! | AE17: =SUM(AD17) -> 0 | AF17: =ROUNDUP(AE17*100/$AE$5,0) -> 0 | AG17: =VLOOKUP(AF17,Grading!$A$1:$B$102,2,TRUE) -> 5 | AI17: =ROUNDUP(AH17*100/$AH$5,0) -> 0 | AJ17: =VLOOKUP(AI17,Grading!$A$1:$B$102,2,TRUE) -> 5 | AK17: =ROUNDDOWN((AC17*0.2)+(AG17*0.2)+(AJ17*0.6),1) -> #DIV/0! | AL17: =IF(AK17<=3,"PASS","FAIL") -> #DIV/0!
A18: 13 | AA18: =SUM(S18:Z18) -> 0 | AB18: =ROUNDUP(AA18*100/$AA$5,0) -> #DIV/0! | AC18: =VLOOKUP(AB18,Grading!$A$1:$B$102,2,TRUE) -> #DIV/0! | AE18: =SUM(AD18) -> 0 | AF18: =ROUNDUP(AE18*100/$AE$5,0) -> 0 | AG18: =VLOOKUP(AF18,Grading!$A$1:$B$102,2,TRUE) -> 5 | AI18: =ROUNDUP(AH18*100/$AH$5,0) -> 0 | AJ18: =VLOOKUP(AI18,Grading!$A$1:$B$102,2,TRUE) -> 5 | AK18: =ROUNDDOWN((AC18*0.2)+(AG18*0.2)+(AJ18*0.6),1) -> #DIV/0! | AL18: =IF(AK18<=3,"PASS","FAIL") -> #DIV/0!
... A47: 42 | AA47: =SUM(S47:Z47) -> 0 | AB47: =ROUNDUP(AA47*100/$AA$5,0) -> #DIV/0! | AC47: =VLOOKUP(AB47,Grading!$A$1:$B$102,2,TRUE) -> #DIV/0! | AE47: =SUM(AD47) -> 0 | AF47: =ROUNDUP(AE47*100/$AE$5,0) -> 0 | AG47: =VLOOKUP(AF47,Grading!$A$1:$B$102,2,TRUE) -> 5 | AI47: =ROUNDUP(AH47*100/$AH$5,0) -> 0 | AJ47: =VLOOKUP(AI47,Grading!$A$1:$B$102,2,TRUE) -> 5 | AK47: =ROUNDDOWN((AC47*0.2)+(AG47*0.2)+(AJ47*0.6),1) -> #DIV/0! | AL47: =IF(AK47<=3,"PASS","FAIL") -> #DIV/0!
AK48: FAIL | AL48: =COUNTIF(AL6:AL47,"FAIL") -> 0
AK49: PASS | AL49: =COUNTIF(AL6:AL47,"PASS") -> 0

Sheet Finals with PT
A1: IPT101
A2: STUDENTS | K2: ATTENDANCE | S2: Activities | AB2: Quiz | AF2: Performance Task | AJ2: Final Exam | AN2: Course Grade
Y3: CA TOTAL | Z3: % | AA3: CA GRADE | AB3: Q2 | AC3: QUIZ TOTAL | AD3: % | AE3: QUIZ GRADE | AF3: PT1 | AG3: PT TOTAL | AH3: % | AI3: PT GRADE | AJ3: E2 | AK3: % | AL3: Final Exam Grade | AM3: Finals Grade | AN3: Midterm Grade | AO3: Course Grade
A4: DATE
A5: TOTAL POINTS | Y5: =SUM(S5:X5) -> 0 | Z5: 100 | AA5: =VLOOKUP(Z5,Grading!A1:B101,2,TRUE) -> 1 | AB5: 40 | AC5: =SUM(AB5) -> 40 | AD5: =ROUNDUP(AC5*100/$AC$5,0) -> 100 | AE5: =VLOOKUP(AD5,Grading!A1:B101,2,TRUE) -> 1 | AF5: 100 | AG5: =SUM(AF5) -> 100 | AH5: =ROUNDUP(AG5*100/$AF$5,0) -> 100 | AJ5: 100 | AK5: =ROUNDUP(AJ5*100/$AJ$5,0) -> 100 | AL5: =VLOOKUP(AK5,Grading!A1:B101,2,TRUE) -> 1 | AM5: =ROUNDDOWN((AA5*0.2)+(AE5*0.2)+(AL5*0.6),1) -> 1
A6: {=_xlfn.SEQUENCE(42,1)} -> 1 | B6: ACHACOSO, Aleann Venice Amor | Y6: =SUM(S6:X6) -> 0 | Z6: =ROUNDUP(Y6*100/$Y$5,0) -> #DIV/0! | AA6: =VLOOKUP(Z6,Grading!$A$1:$B$102,2,TRUE) -> #DIV/0! | AC6: =SUM(AB6) -> 0 | AD6: =ROUNDUP(AC6*100/$AC$5,0) -> 0 | AE6: =VLOOKUP(AD6,Grading!$A$1:$B$102,2,TRUE) -> 5 | AG6: =SUM(AF6) -> 0 | AH6: =ROUNDUP(AG6*100/$AF$5,0) -> 0 | AI6: =VLOOKUP(AH6,Grading!$A$1:$B$102,2,TRUE) -> 5 | AK6: =ROUNDUP(AJ6*100/$AJ$5,0) -> 0 | AL6: =VLOOKUP(AK6,Grading!$A$1:$B$102,2,TRUE) -> 5 | AM6: =ROUNDDOWN((AA6*0.1)+(AE6*0.2)+(AI6*0.4)+(AL6*0.3),1) -> #DIV/0! | AN6: =Midterms!AK6 -> #DIV/0! | AO6: =(AM6*0.5)+(AN6*0.5) -> #DIV/0!
A7: 2 | B7: AGUM, Gideon Rey Cadeliña | Y7: =SUM(S7:X7) -> 0 | Z7: =ROUNDUP(Y7*100/$Y$5,0) -> #DIV/0! | AA7: =VLOOKUP(Z7,Grading!$A$1:$B$102,2,TRUE) -> #DIV/0! | AC7: =SUM(AB7) -> 0 | AD7: =ROUNDUP(AC7*100/$AC$5,0) -> 0 | AE7: =VLOOKUP(AD7,Grading!$A$1:$B$102,2,TRUE) -> 5 | AG7: =SUM(AF7) -> 0 | AH7: =ROUNDUP(AG7*100/$AF$5,0) -> 0 | AI7: =VLOOKUP(AH7,Grading!$A$1:$B$102,2,TRUE) -> 5 | AK7: =ROUNDUP(AJ7*100/$AJ$5,0) -> 0 | AL7: =VLOOKUP(AK7,Grading!$A$1:$B$102,2,TRUE) -> 5 | AM7: =ROUNDDOWN((AA7*0.1)+(AE7*0.2)+(AI7*0.4)+(AL7*0.3),1) -> #DIV/0! | AN7: =Midterms!AK7 -> #DIV/0! | AO7: =(AM7*0.5)+(AN7*0.5) -> #DIV/0!
A8: 3 | B8: ALCALA, John Niño Mikhael Tenorio | Y8: =SUM(S8:X8) -> 0 | Z8: =ROUNDUP(Y8*100/$Y$5,0) -> #DIV/0! | AA8: =VLOOKUP(Z8,Grading!$A$1:$B$102,2,TRUE) -> #DIV/0! | AC8: =SUM(AB8) -> 0 | AD8: =ROUNDUP(AC8*100/$AC$5,0) -> 0 | AE8: =VLOOKUP(AD8,Grading!$A$1:$B$102,2,TRUE) -> 5 | AG8: =SUM(AF8) -> 0 | AH8: =ROUNDUP(AG8*100/$AF$5,0) -> 0 | AI8: =VLOOKUP(AH8,Grading!$A$1:$B$102,2,TRUE) -> 5 | AK8: =ROUNDUP(AJ8*100/$AJ$5,0) -> 0 | AL8: =VLOOKUP(AK8,Grading!$A$1:$B$102,2,TRUE) -> 5 | AM8: =ROUNDDOWN((AA8*0.1)+(AE8*0.2)+(AI8*0.4)+(AL8*0.3),1) -> #DIV/0! | AN8: =Midterms!AK8 -> #DIV/0! | AO8: =(AM8*0.5)+(AN8*0.5) -> #DIV/0!
A9: 4 | Y9: =SUM(S9:X9) -> 0 | Z9: =ROUNDUP(Y9*100/$Y$5,0) -> #DIV/0! | AA9: =VLOOKUP(Z9,Grading!$A$1:$B$102,2,TRUE) -> #DIV/0! | AC9: =SUM(AB9) -> 0 | AD9: =ROUNDUP(AC9*100/$AC$5,0) -> 0 | AE9: =VLOOKUP(AD9,Grading!$A$1:$B$102,2,TRUE) -> 5 | AG9: =SUM(AF9) -> 0 | AH9: =ROUNDUP(AG9*100/$AF$5,0) -> 0 | AI9: =VLOOKUP(AH9,Grading!$A$1:$B$102,2,TRUE) -> 5 | AK9: =ROUNDUP(AJ9*100/$AJ$5,0) -> 0 | AL9: =VLOOKUP(AK9,Grading!$A$1:$B$102,2,TRUE) -> 5 | AM9: =ROUNDDOWN((AA9*0.1)+(AE9*0.2)+(AI9*0.4)+(AL9*0.3),1) -> #DIV/0! | AN9: =Midterms!AK9 -> #DIV/0! | AO9: =(AM9*0.5)+(AN9*0.5) -> #DIV/0!
A10: 5 | Y10: =SUM(S10:X10) -> 0 | Z10: =ROUNDUP(Y10*100/$Y$5,0) -> #DIV/0! | AA10: =VLOOKUP(Z10,Grading!$A$1:$B$102,2,TRUE) -> #DIV/0! | AC10: =SUM(AB10) -> 0 | AD10: =ROUNDUP(AC10*100/$AC$5,0) -> 0 | AE10: =VLOOKUP(AD10,Grading!$A$1:$B$102,2,TRUE) -> 5 | AG10: =SUM(AF10) -> 0 | AH10: =ROUNDUP(AG10*100/$AF$5,0) -> 0 | AI10: =VLOOKUP(AH10,Grading!$A$1:$B$102,2,TRUE) -> 5 | AK10: =ROUNDUP(AJ10*100/$AJ$5,0) -> 0 | AL10: =VLOOKUP(AK10,Grading!$A$1:$B$102,2,TRUE) -> 5 | AM10: =ROUNDDOWN((AA10*0.1)+(AE10*0.2)+(AI10*0.4)+(AL10*0.3),1) -> #DIV/0! | AN10: =Midterms!AK10 -> #DIV/0! | AO10: =(AM10*0.5)+(AN10*0.5) -> #DIV/0!
A11: 6 | Y11: =SUM(S11:X11) -> 0 | Z11: =ROUNDUP(Y11*100/$Y$5,0) -> #DIV/0! | AA11: =VLOOKUP(Z11,Grading!$A$1:$B$102,2,TRUE) -> #DIV/0! | AC11: =SUM(AB11) -> 0 | AD11: =ROUNDUP(AC11*100/$AC$5,0) -> 0 | AE11: =VLOOKUP(AD11,Grading!$A$1:$B$102,2,TRUE) -> 5 | AG11: =SUM(AF11) -> 0 | AH11: =ROUNDUP(AG11*100/$AF$5,0) -> 0 | AI11: =VLOOKUP(AH11,Grading!$A$1:$B$102,2,TRUE) -> 5 | AK11: =ROUNDUP(AJ11*100/$AJ$5,0) -> 0 | AL11: =VLOOKUP(AK11,Grading!$A$1:$B$102,2,TRUE) -> 5 | AM11: =ROUNDDOWN((AA11*0.1)+(AE11*0.2)+(AI11*0.4)+(AL11*0.3),1) -> #DIV/0! | AN11: =Midterms!AK11 -> #DIV/0! | AO11: =(AM11*0.5)+(AN11*0.5) -> #DIV/0!
A12: 7 | Y12: =SUM(S12:X12) -> 0 | Z12: =ROUNDUP(Y12*100/$Y$5,0) -> #DIV/0! | AA12: =VLOOKUP(Z12,Grading!$A$1:$B$102,2,TRUE) -> #DIV/0! | AC12: =SUM(AB12) -> 0 | AD12: =ROUNDUP(AC12*100/$AC$5,0) -> 0 | AE12: =VLOOKUP(AD12,Grading!$A$1:$B$102,2,TRUE) -> 5 | AG12: =SUM(AF12) -> 0 | AH12: =ROUNDUP(AG12*100/$AF$5,0) -> 0 | AI12: =VLOOKUP(AH12,Grading!$A$1:$B$102,2,TRUE) -> 5 | AK12: =ROUNDUP(AJ12*100/$AJ$5,0) -> 0 | AL12: =VLOOKUP(AK12,Grading!$A$1:$B$102,2,TRUE) -> 5 | AM12: =ROUNDDOWN((AA12*0.1)+(AE12*0.2)+(AI12*0.4)+(AL12*0.3),1) -> #DIV/0! | AN12: =Midterms!AK12 -> #DIV/0! | AO12: =(AM12*0.5)+(AN12*0.5) -> #DIV/0!
A13: 8 | Y13: =SUM(S13:X13) -> 0 | Z13: =ROUNDUP(Y13*100/$Y$5,0) -> #DIV/0! | AA13: =VLOOKUP(Z13,Grading!$A$1:$B$102,2,TRUE) -> #DIV/0! | AC13: =SUM(AB13) -> 0 | AD13: =ROUNDUP(AC13*100/$AC$5,0) -> 0 | AE13: =VLOOKUP(AD13,Grading!$A$1:$B$102,2,TRUE) -> 5 | AG13: =SUM(AF13) -> 0 | AH13: =ROUNDUP(AG13*100/$AF$5,0) -> 0 | AI13: =VLOOKUP(AH13,Grading!$A$1:$B$102,2,TRUE) -> 5 | AK13: =ROUNDUP(AJ13*100/$AJ$5,0) -> 0 | AL13: =VLOOKUP(AK13,Grading!$A$1:$B$102,2,TRUE) -> 5 | AM13: =ROUNDDOWN((AA13*0.1)+(AE13*0.2)+(AI13*0.4)+(AL13*0.3),1) -> #DIV/0! | AN13: =Midterms!AK13 -> #DIV/0! | AO13: =(AM13*0.5)+(AN13*0.5) -> #DIV/0!
A14: 9 | Y14: =SUM(S14:X14) -> 0 | Z14: =ROUNDUP(Y14*100/$Y$5,0) -> #DIV/0! | AA14: =VLOOKUP(Z14,Grading!$A$1:$B$102,2,TRUE) -> #DIV/0! | AC14: =SUM(AB14) -> 0 | AD14: =ROUNDUP(AC14*100/$AC$5,0) -> 0 | AE14: =VLOOKUP(AD14,Grading!$A$1:$B$102,2,TRUE) -> 5 | AG14: =SUM(AF14) -> 0 | AH14: =ROUNDUP(AG14*100/$AF$5,0) -> 0 | AI14: =VLOOKUP(AH14,Grading!$A$1:$B$102,2,TRUE) -> 5 | AK14: =ROUNDUP(AJ14*100/$AJ$5,0) -> 0 | AL14: =VLOOKUP(AK14,Grading!$A$1:$B$102,2,TRUE) -> 5 | AM14: =ROUNDDOWN((AA14*0.1)+(AE14*0.2)+(AI14*0.4)+(AL14*0.3),1) -> #DIV/0! | AN14: =Midterms!AK14 -> #DIV/0! | AO14: =(AM14*0.5)+(AN14*0.5) -> #DIV/0!
A15: 10 | Y15: =SUM(S15:X15) -> 0 | Z15: =ROUNDUP(Y15*100/$Y$5,0) -> #DIV/0! | AA15: =VLOOKUP(Z15,Grading!$A$1:$B$102,2,TRUE) -> #DIV/0! | AC15: =SUM(AB15) -> 0 | AD15: =ROUNDUP(AC15*100/$AC$5,0) -> 0 | AE15: =VLOOKUP(AD15,Grading!$A$1:$B$102,2,TRUE) -> 5 | AG15: =SUM(AF15) -> 0 | AH15: =ROUNDUP(AG15*100/$AF$5,0) -> 0 | AI15: =VLOOKUP(AH15,Grading!$A$1:$B$102,2,TRUE) -> 5 | AK15: =ROUNDUP(AJ15*100/$AJ$5,0) -> 0 | AL15: =VLOOKUP(AK15,Grading!$A$1:$B$102,2,TRUE) -> 5 | AM15: =ROUNDDOWN((AA15*0.1)+(AE15*0.2)+(AI15*0.4)+(AL15*0.3),1) -> #DIV/0! | AN15: =Midterms!AK15 -> #DIV/0! | AO15: =(AM15*0.5)+(AN15*0.5) -> #DIV/0!
A16: 11 | Y16: =SUM(S16:X16) -> 0 | Z16: =ROUNDUP(Y16*100/$Y$5,0) -> #DIV/0! | AA16: =VLOOKUP(Z16,Grading!$A$1:$B$102,2,TRUE) -> #DIV/0! | AC16: =SUM(AB16) -> 0 | AD16: =ROUNDUP(AC16*100/$AC$5,0) -> 0 | AE16: =VLOOKUP(AD16,Grading!$A$1:$B$102,2,TRUE) -> 5 | AG16: =SUM(AF16) -> 0 | AH16: =ROUNDUP(AG16*100/$AF$5,0) -> 0 | AI16: =VLOOKUP(AH16,Grading!$A$1:$B$102,2,TRUE) -> 5 | AK16: =ROUNDUP(AJ16*100/$AJ$5,0) -> 0 | AL16: =VLOOKUP(AK16,Grading!$A$1:$B$102,2,TRUE) -> 5 | AM16: =ROUNDDOWN((AA16*0.1)+(AE16*0.2)+(AI16*0.4)+(AL16*0.3),1) -> #DIV/0! | AN16: =Midterms!AK16 -> #DIV/0! | AO16: =(AM16*0.5)+(AN16*0.5) -> #DIV/0!
A17: 12 | Y17: =SUM(S17:X17) -> 0 | Z17: =ROUNDUP(Y17*100/$Y$5,0) -> #DIV/0! | AA17: =VLOOKUP(Z17,Grading!$A$1:$B$102,2,TRUE) -> #DIV/0! | AC17: =SUM(AB17) -> 0 | AD17: =ROUNDUP(AC17*100/$AC$5,0) -> 0 | AE17: =VLOOKUP(AD17,Grading!$A$1:$B$102,2,TRUE) -> 5 | AG17: =SUM(AF17) -> 0 | AH17: =ROUNDUP(AG17*100/$AF$5,0) -> 0 | AI17: =VLOOKUP(AH17,Grading!$A$1:$B$102,2,TRUE) -> 5 | AK17: =ROUNDUP(AJ17*100/$AJ$5,0) -> 0 | AL17: =VLOOKUP(AK17,Grading!$A$1:$B$102,2,TRUE) -> 5 | AM17: =ROUNDDOWN((AA17*0.1)+(AE17*0.2)+(AI17*0.4)+(AL17*0.3),1) -> #DIV/0! | AN17: =Midterms!AK17 -> #DIV/0! | AO17: =(AM17*0.5)+(AN17*0.5) -> #DIV/0!
A18: 13 | Y18: =SUM(S18:X18) -> 0 | Z18: =ROUNDUP(Y18*100/$Y$5,0) -> #DIV/0! | AA18: =VLOOKUP(Z18,Grading!$A$1:$B$102,2,TRUE) -> #DIV/0! | AC18: =SUM(AB18) -> 0 | AD18: =ROUNDUP(AC18*100/$AC$5,0) -> 0 | AE18: =VLOOKUP(AD18,Grading!$A$1:$B$102,2,TRUE) -> 5 | AG18: =SUM(AF18) -> 0 | AH18: =ROUNDUP(AG18*100/$AF$5,0) -> 0 | AI18: =VLOOKUP(AH18,Grading!$A$1:$B$102,2,TRUE) -> 5 | AK18: =ROUNDUP(AJ18*100/$AJ$5,0) -> 0 | AL18: =VLOOKUP(AK18,Grading!$A$1:$B$102,2,TRUE) -> 5 | AM18: =ROUNDDOWN((AA18*0.1)+(AE18*0.2)+(AI18*0.4)+(AL18*0.3),1) -> #DIV/0! | AN18: =Midterms!AK18 -> #DIV/0! | AO18: =(AM18*0.5)+(AN18*0.5) -> #DIV/0!
A19: 14 | Y19: =SUM(S19:X19) -> 0 | Z19: =ROUNDUP(Y19*100/$Y$5,0) -> #DIV/0! | AA19: =VLOOKUP(Z19,Grading!$A$1:$B$102,2,TRUE) -> #DIV/0! | AC19: =SUM(AB19) -> 0 | AD19: =ROUNDUP(AC19*100/$AC$5,0) -> 0 | AE19: =VLOOKUP(AD19,Grading!$A$1:$B$102,2,TRUE) -> 5 | AG19: =SUM(AF19) -> 0 | AH19: =ROUNDUP(AG19*100/$AF$5,0) -> 0 | AI19: =VLOOKUP(AH19,Grading!$A$1:$B$102,2,TRUE) -> 5 | AK19: =ROUNDUP(AJ19*100/$AJ$5,0) -> 0 | AL19: =VLOOKUP(AK19,Grading!$A$1:$B$102,2,TRUE) -> 5 | AM19: =ROUNDDOWN((AA19*0.1)+(AE19*0.2)+(AI19*0.4)+(AL19*0.3),1) -> #DIV/0! | AN19: =Midterms!AK19 -> #DIV/0! | AO19: =(AM19*0.5)+(AN19*0.5) -> #DIV/0!
A20: 15 | Y20: =SUM(S20:X20) -> 0 | Z20: =ROUNDUP(Y20*100/$Y$5,0) -> #DIV/0! | AA20: =VLOOKUP(Z20,Grading!$A$1:$B$102,2,TRUE) -> #DIV/0! | AC20: =SUM(AB20) -> 0 | AD20: =ROUNDUP(AC20*100/$AC$5,0) -> 0 | AE20: =VLOOKUP(AD20,Grading!$A$1:$B$102,2,TRUE) -> 5 | AG20: =SUM(AF20) -> 0 | AH20: =ROUNDUP(AG20*100/$AF$5,0) -> 0 | AI20: =VLOOKUP(AH20,Grading!$A$1:$B$102,2,TRUE) -> 5 | AK20: =ROUNDUP(AJ20*100/$AJ$5,0) -> 0 | AL20: =VLOOKUP(AK20,Grading!$A$1:$B$102,2,TRUE) -> 5 | AM20: =ROUNDDOWN((AA20*0.1)+(AE20*0.2)+(AI20*0.4)+(AL20*0.3),1) -> #DIV/0! | AN20: =Midterms!AK20 -> #DIV/0! | AO20: =(AM20*0.5)+(AN20*0.5) -> #DIV/0!
... A22: 17 | Y22: =SUM(S22:X22) -> 0 | Z22: =ROUNDUP(Y22*100/$Y$5,0) -> #DIV/0! | AA22: =VLOOKUP(Z22,Grading!$A$1:$B$102,2,TRUE) -> #DIV/0! | AC22: =SUM(AB22) -> 0 | AD22: =ROUNDUP(AC22*100/$AC$5,0) -> 0 | AE22: =VLOOKUP(AD22,Grading!$A$1:$B$102,2,TRUE) -> 5 | AG22: =SUM(AF22) -> 0 | AH22: =ROUNDUP(AG22*100/$AF$5,0) -> 0 | AI22: =VLOOKUP(AH22,Grading!$A$1:$B$102,2,TRUE) -> 5 | AK22: =ROUNDUP(AJ22*100/$AJ$5,0) -> 0 | AL22: =VLOOKUP(AK22,Grading!$A$1:$B$102,2,TRUE) -> 5 | AM22: =ROUNDDOWN((AA22*0.1)+(AE22*0.2)+(AI22*0.4)+(AL22*0.3),1) -> #DIV/0! | AN22: =Midterms!AK22 -> #DIV/0! | AO22: =(AM22*0.5)+(AN22*0.5) -> #DIV/0!
A23: 18 | Y23: =SUM(S23:X23) -> 0 | Z23: =ROUNDUP(Y23*100/$Y$5,0) -> #DIV/0! | AA23: =VLOOKUP(Z23,Grading!$A$1:$B$102,2,TRUE) -> #DIV/0! | AC23: =SUM(AB23) -> 0 | AD23: =ROUNDUP(AC23*100/$AC$5,0) -> 0 | AE23: =VLOOKUP(AD23,Grading!$A$1:$B$102,2,TRUE) -> 5 | AG23: =SUM(AF23) -> 0 | AH23: =ROUNDUP(AG23*100/$AF$5,0) -> 0 | AI23: =VLOOKUP(AH23,Grading!$A$1:$B$102,2,TRUE) -> 5 | AK23: =ROUNDUP(AJ23*100/$AJ$5,0) -> 0 | AL23: =VLOOKUP(AK23,Grading!$A$1:$B$102,2,TRUE) -> 5 | AM23: =ROUNDDOWN((AA23*0.1)+(AE23*0.2)+(AI23*0.4)+(AL23*0.3),1) -> #DIV/0! | AN23: =Midterms!AK23 -> #DIV/0! | AO23: =(AM23*0.5)+(AN23*0.5) -> #DIV/0! | AP23: INC
A24: 19 | Y24: =SUM(S24:X24) -> 0 | Z24: =ROUNDUP(Y24*100/$Y$5,0) -> #DIV/0! | AA24: =VLOOKUP(Z24,Grading!$A$1:$B$102,2,TRUE) -> #DIV/0! | AC24: =SUM(AB24) -> 0 | AD24: =ROUNDUP(AC24*100/$AC$5,0) -> 0 | AE24: =VLOOKUP(AD24,Grading!$A$1:$B$102,2,TRUE) -> 5 | AG24: =SUM(AF24) -> 0 | AH24: =ROUNDUP(AG24*100/$AF$5,0) -> 0 | AI24: =VLOOKUP(AH24,Grading!$A$1:$B$102,2,TRUE) -> 5 | AK24: =ROUNDUP(AJ24*100/$AJ$5,0) -> 0 | AL24: =VLOOKUP(AK24,Grading!$A$1:$B$102,2,TRUE) -> 5 | AM24: =ROUNDDOWN((AA24*0.1)+(AE24*0.2)+(AI24*0.4)+(AL24*0.3),1) -> #DIV/0! | AN24: =Midterms!AK24 -> #DIV/0! | AO24: =(AM24*0.5)+(AN24*0.5) -> #DIV/0!
A25: 20 | Y25: =SUM(S25:X25) -> 0 | Z25: =ROUNDUP(Y25*100/$Y$5,0) -> #DIV/0! | AA25: =VLOOKUP(Z25,Grading!$A$1:$B$102,2,TRUE) -> #DIV/0! | AC25: =SUM(AB25) -> 0 | AD25: =ROUNDUP(AC25*100/$AC$5,0) -> 0 | AE25: =VLOOKUP(AD25,Grading!$A$1:$B$102,2,TRUE) -> 5 | AG25: =SUM(AF25) -> 0 | AH25: =ROUNDUP(AG25*100/$AF$5,0) -> 0 | AI25: =VLOOKUP(AH25,Grading!$A$1:$B$102,2,TRUE) -> 5 | AK25: =ROUNDUP(AJ25*100/$AJ$5,0) -> 0 | AL25: =VLOOKUP(AK25,Grading!$A$1:$B$102,2,TRUE) -> 5 | AM25: =ROUNDDOWN((AA25*0.1)+(AE25*0.2)+(AI25*0.4)+(AL25*0.3),1) -> #DIV/0! | AN25: =Midterms!AK25 -> #DIV/0! | AO25: =(AM25*0.5)+(AN25*0.5) -> #DIV/0!
A26: 21 | Y26: =SUM(S26:X26) -> 0 | Z26: =ROUNDUP(Y26*100/$Y$5,0) -> #DIV/0! | AA26: =VLOOKUP(Z26,Grading!$A$1:$B$102,2,TRUE) -> #DIV/0! | AC26: =SUM(AB26) -> 0 | AD26: =ROUNDUP(AC26*100/$AC$5,0) -> 0 | AE26: =VLOOKUP(AD26,Grading!$A$1:$B$102,2,TRUE) -> 5 | AG26: =SUM(AF26) -> 0 | AH26: =ROUNDUP(AG26*100/$AF$5,0) -> 0 | AI26: =VLOOKUP(AH26,Grading!$A$1:$B$102,2,TRUE) -> 5 | AK26: =ROUNDUP(AJ26*100/$AJ$5,0) -> 0 | AL26: =VLOOKUP(AK26,Grading!$A$1:$B$102,2,TRUE) -> 5 | AM26: =ROUNDDOWN((AA26*0.1)+(AE26*0.2)+(AI26*0.4)+(AL26*0.3),1) -> #DIV/0! | AN26: =Midterms!AK26 -> #DIV/0! | AO26: =(AM26*0.5)+(AN26*0.5) -> #DIV/0!
A27: 22 | Y27: =SUM(S27:X27) -> 0 | Z27: =ROUNDUP(Y27*100/$Y$5,0) -> #DIV/0! | AA27: =VLOOKUP(Z27,Grading!$A$1:$B$102,2,TRUE) -> #DIV/0! | AC27: =SUM(AB27) -> 0 | AD27: =ROUNDUP(AC27*100/$AC$5,0) -> 0 | AE27: =VLOOKUP(AD27,Grading!$A$1:$B$102,2,TRUE) -> 5 | AG27: =SUM(AF27) -> 0 | AH27: =ROUNDUP(AG27*100/$AF$5,0) -> 0 | AI27: =VLOOKUP(AH27,Grading!$A$1:$B$102,2,TRUE) -> 5 | AK27: =ROUNDUP(AJ27*100/$AJ$5,0) -> 0 | AL27: =VLOOKUP(AK27,Grading!$A$1:$B$102,2,TRUE) -> 5 | AM27: =ROUNDDOWN((AA27*0.1)+(AE27*0.2)+(AI27*0.4)+(AL27*0.3),1) -> #DIV/0! | AN27: =Midterms!AK27 -> #DIV/0! | AO27: =(AM27*0.5)+(AN27*0.5) -> #DIV/0!
A28: 23 | Y28: =SUM(S28:X28) -> 0 | Z28: =ROUNDUP(Y28*100/$Y$5,0) -> #DIV/0! | AA28: =VLOOKUP(Z28,Grading!$A$1:$B$102,2,TRUE) -> #DIV/0! | AC28: =SUM(AB28) -> 0 | AD28: =ROUNDUP(AC28*100/$AC$5,0) -> 0 | AE28: =VLOOKUP(AD28,Grading!$A$1:$B$102,2,TRUE) -> 5 | AG28: =SUM(AF28) -> 0 | AH28: =ROUNDUP(AG28*100/$AF$5,0) -> 0 | AI28: =VLOOKUP(AH28,Grading!$A$1:$B$102,2,TRUE) -> 5 | AK28: =ROUNDUP(AJ28*100/$AJ$5,0) -> 0 | AL28: =VLOOKUP(AK28,Grading!$A$1:$B$102,2,TRUE) -> 5 | AM28: =ROUNDDOWN((AA28*0.1)+(AE28*0.2)+(AI28*0.4)+(AL28*0.3),1) -> #DIV/0! | AN28: =Midterms!AK28 -> #DIV/0! | AO28: =(AM28*0.5)+(AN28*0.5) -> #DIV/0! | AP28: INC
A29: 24 | Y29: =SUM(S29:X29) -> 0 | Z29: =ROUNDUP(Y29*100/$Y$5,0) -> #DIV/0! | AA29: =VLOOKUP(Z29,Grading!$A$1:$B$102,2,TRUE) -> #DIV/0! | AC29: =SUM(AB29) -> 0 | AD29: =ROUNDUP(AC29*100/$AC$5,0) -> 0 | AE29: =VLOOKUP(AD29,Grading!$A$1:$B$102,2,TRUE) -> 5 | AG29: =SUM(AF29) -> 0 | AH29: =ROUNDUP(AG29*100/$AF$5,0) -> 0 | AI29: =VLOOKUP(AH29,Grading!$A$1:$B$102,2,TRUE) -> 5 | AK29: =ROUNDUP(AJ29*100/$AJ$5,0) -> 0 | AL29: =VLOOKUP(AK29,Grading!$A$1:$B$102,2,TRUE) -> 5 | AM29: =ROUNDDOWN((AA29*0.1)+(AE29*0.2)+(AI29*0.4)+(AL29*0.3),1) -> #DIV/0! | AN29: =Midterms!AK29 -> #DIV/0! | AO29: =(AM29*0.5)+(AN29*0.5) -> #DIV/0!
A30: 25 | Y30: =SUM(S30:X30) -> 0 | Z30: =ROUNDUP(Y30*100/$Y$5,0) -> #DIV/0! | AA30: =VLOOKUP(Z30,Grading!$A$1:$B$102,2,TRUE) -> #DIV/0! | AC30: =SUM(AB30) -> 0 | AD30: =ROUNDUP(AC30*100/$AC$5,0) -> 0 | AE30: =VLOOKUP(AD30,Grading!$A$1:$B$102,2,TRUE) -> 5 | AG30: =SUM(AF30) -> 0 | AH30: =ROUNDUP(AG30*100/$AF$5,0) -> 0 | AI30: =VLOOKUP(AH30,Grading!$A$1:$B$102,2,TRUE) -> 5 | AK30: =ROUNDUP(AJ30*100/$AJ$5,0) -> 0 | AL30: =VLOOKUP(AK30,Grading!$A$1:$B$102,2,TRUE) -> 5 | AM30: =ROUNDDOWN((AA30*0.1)+(AE30*0.2)+(AI30*0.4)+(AL30*0.3),1) -> #DIV/0! | AN30: =Midterms!AK30 -> #DIV/0! | AO30: =(AM30*0.5)+(AN30*0.5) -> #DIV/0!
A31: 26 | Y31: =SUM(S31:X31) -> 0 | Z31: =ROUNDUP(Y31*100/$Y$5,0) -> #DIV/0! | AA31: =VLOOKUP(Z31,Grading!$A$1:$B$102,2,TRUE) -> #DIV/0! | AC31: =SUM(AB31) -> 0 | AD31: =ROUNDUP(AC31*100/$AC$5,0) -> 0 | AE31: =VLOOKUP(AD31,Grading!$A$1:$B$102,2,TRUE) -> 5 | AG31: =SUM(AF31) -> 0 | AH31: =ROUNDUP(AG31*100/$AF$5,0) -> 0 | AI31: =VLOOKUP(AH31,Grading!$A$1:$B$102,2,TRUE) -> 5 | AK31: =ROUNDUP(AJ31*100/$AJ$5,0) -> 0 | AL31: =VLOOKUP(AK31,Grading!$A$1:$B$102,2,TRUE) -> 5 | AM31: =ROUNDDOWN((AA31*0.1)+(AE31*0.2)+(AI31*0.4)+(AL31*0.3),1) -> #DIV/0! | AN31: =Midterms!AK31 -> #DIV/0! | AO31: =(AM31*0.5)+(AN31*0.5) -> #DIV/0!
A32: 27 | Y32: =SUM(S32:X32) -> 0 | Z32: =ROUNDUP(Y32*100/$Y$5,0) -> #DIV/0! | AA32: =VLOOKUP(Z32,Grading!$A$1:$B$102,2,TRUE) -> #DIV/0! | AC32: =SUM(AB32) -> 0 | AD32: =ROUNDUP(AC32*100/$AC$5,0) -> 0 | AE32: =VLOOKUP(AD32,Grading!$A$1:$B$102,2,TRUE) -> 5 | AG32: =SUM(AF32) -> 0 | AH32: =ROUNDUP(AG32*100/$AF$5,0) -> 0 | AI32: =VLOOKUP(AH32,Grading!$A$1:$B$102,2,TRUE) -> 5 | AK32: =ROUNDUP(AJ32*100/$AJ$5,0) -> 0 | AL32: =VLOOKUP(AK32,Grading!$A$1:$B$102,2,TRUE) -> 5 | AM32: =ROUNDDOWN((AA32*0.1)+(AE32*0.2)+(AI32*0.4)+(AL32*0.3),1) -> #DIV/0! | AN32: =Midterms!AK32 -> #DIV/0! | AO32: =(AM32*0.5)+(AN32*0.5) -> #DIV/0!
A33: 28 | Y33: =SUM(S33:X33) -> 0 | Z33: =ROUNDUP(Y33*100/$Y$5,0) -> #DIV/0! | AA33: =VLOOKUP(Z33,Grading!$A$1:$B$102,2,TRUE) -> #DIV/0! | AC33: =SUM(AB33) -> 0 | AD33: =ROUNDUP(AC33*100/$AC$5,0) -> 0 | AE33: =VLOOKUP(AD33,Grading!$A$1:$B$102,2,TRUE) -> 5 | AG33: =SUM(AF33) -> 0 | AH33: =ROUNDUP(AG33*100/$AF$5,0) -> 0 | AI33: =VLOOKUP(AH33,Grading!$A$1:$B$102,2,TRUE) -> 5 | AK33: =ROUNDUP(AJ33*100/$AJ$5,0) -> 0 | AL33: =VLOOKUP(AK33,Grading!$A$1:$B$102,2,TRUE) -> 5 | AM33: =ROUNDDOWN((AA33*0.1)+(AE33*0.2)+(AI33*0.4)+(AL33*0.3),1) -> #DIV/0! | AN33: =Midterms!AK33 -> #DIV/0! | AO33: =(AM33*0.5)+(AN33*0.5) -> #DIV/0!
A34: 29 | Y34: =SUM(S34:X34) -> 0 | Z34: =ROUNDUP(Y34*100/$Y$5,0) -> #DIV/0! | AA34: =VLOOKUP(Z34,Grading!$A$1:$B$102,2,TRUE) -> #DIV/0! | AC34: =SUM(AB34) -> 0 | AD34: =ROUNDUP(AC34*100/$AC$5,0) -> 0 | AE34: =VLOOKUP(AD34,Grading!$A$1:$B$102,2,TRUE) -> 5 | AG34: =SUM(AF34) -> 0 | AH34: =ROUNDUP(AG34*100/$AF$5,0) -> 0 | AI34: =VLOOKUP(AH34,Grading!$A$1:$B$102,2,TRUE) -> 5 | AK34: =ROUNDUP(AJ34*100/$AJ$5,0) -> 0 | AL34: =VLOOKUP(AK34,Grading!$A$1:$B$102,2,TRUE) -> 5 | AM34: =ROUNDDOWN((AA34*0.1)+(AE34*0.2)+(AI34*0.4)+(AL34*0.3),1) -> #DIV/0! | AN34: =Midterms!AK34 -> #DIV/0! | AO34: =(AM34*0.5)+(AN34*0.5) -> #DIV/0!
A35: 30 | Y35: =SUM(S35:X35) -> 0 | Z35: =ROUNDUP(Y35*100/$Y$5,0) -> #DIV/0! | AA35: =VLOOKUP(Z35,Grading!$A$1:$B$102,2,TRUE) -> #DIV/0! | AC35: =SUM(AB35) -> 0 | AD35: =ROUNDUP(AC35*100/$AC$5,0) -> 0 | AE35: =VLOOKUP(AD35,Grading!$A$1:$B$102,2,TRUE) -> 5 | AG35: =SUM(AF35) -> 0 | AH35: =ROUNDUP(AG35*100/$AF$5,0) -> 0 | AI35: =VLOOKUP(AH35,Grading!$A$1:$B$102,2,TRUE) -> 5 | AK35: =ROUNDUP(AJ35*100/$AJ$5,0) -> 0 | AL35: =VLOOKUP(AK35,Grading!$A$1:$B$102,2,TRUE) -> 5 | AM35: =ROUNDDOWN((AA35*0.1)+(AE35*0.2)+(AI35*0.4)+(AL35*0.3),1) -> #DIV/0! | AN35: =Midterms!AK35 -> #DIV/0! | AO35: =(AM35*0.5)+(AN35*0.5) -> #DIV/0!
A36: 31 | Y36: =SUM(S36:X36) -> 0 | Z36: =ROUNDUP(Y36*100/$Y$5,0) -> #DIV/0! | AA36: =VLOOKUP(Z36,Grading!$A$1:$B$102,2,TRUE) -> #DIV/0! | AC36: =SUM(AB36) -> 0 | AD36: =ROUNDUP(AC36*100/$AC$5,0) -> 0 | AE36: =VLOOKUP(AD36,Grading!$A$1:$B$102,2,TRUE) -> 5 | AG36: =SUM(AF36) -> 0 | AH36: =ROUNDUP(AG36*100/$AF$5,0) -> 0 | AI36: =VLOOKUP(AH36,Grading!$A$1:$B$102,2,TRUE) -> 5 | AK36: =ROUNDUP(AJ36*100/$AJ$5,0) -> 0 | AL36: =VLOOKUP(AK36,Grading!$A$1:$B$102,2,TRUE) -> 5 | AM36: =ROUNDDOWN((AA36*0.1)+(AE36*0.2)+(AI36*0.4)+(AL36*0.3),1) -> #DIV/0! | AN36: =Midterms!AK36 -> #DIV/0! | AO36: =(AM36*0.5)+(AN36*0.5) -> #DIV/0!
A37: 32 | Y37: =SUM(S37:X37) -> 0 | Z37: =ROUNDUP(Y37*100/$Y$5,0) -> #DIV/0! | AA37: =VLOOKUP(Z37,Grading!$A$1:$B$102,2,TRUE) -> #DIV/0! | AC37: =SUM(AB37) -> 0 | AD37: =ROUNDUP(AC37*100/$AC$5,0) -> 0 | AE37: =VLOOKUP(AD37,Grading!$A$1:$B$102,2,TRUE) -> 5 | AG37: =SUM(AF37) -> 0 | AH37: =ROUNDUP(AG37*100/$AF$5,0) -> 0 | AI37: =VLOOKUP(AH37,Grading!$A$1:$B$102,2,TRUE) -> 5 | AK37: =ROUNDUP(AJ37*100/$AJ$5,0) -> 0 | AL37: =VLOOKUP(AK37,Grading!$A$1:$B$102,2,TRUE) -> 5 | AM37: =ROUNDDOWN((AA37*0.1)+(AE37*0.2)+(AI37*0.4)+(AL37*0.3),1) -> #DIV/0! | AN37: =Midterms!AK37 -> #DIV/0! | AO37: =(AM37*0.5)+(AN37*0.5) -> #DIV/0! | AP37: INC
A38: 33 | Y38: =SUM(S38:X38) -> 0 | Z38: =ROUNDUP(Y38*100/$Y$5,0) -> #DIV/0! | AA38: =VLOOKUP(Z38,Grading!$A$1:$B$102,2,TRUE) -> #DIV/0! | AC38: =SUM(AB38) -> 0 | AD38: =ROUNDUP(AC38*100/$AC$5,0) -> 0 | AE38: =VLOOKUP(AD38,Grading!$A$1:$B$102,2,TRUE) -> 5 | AG38: =SUM(AF38) -> 0 | AH38: =ROUNDUP(AG38*100/$AF$5,0) -> 0 | AI38: =VLOOKUP(AH38,Grading!$A$1:$B$102,2,TRUE) -> 5 | AK38: =ROUNDUP(AJ38*100/$AJ$5,0) -> 0 | AL38: =VLOOKUP(AK38,Grading!$A$1:$B$102,2,TRUE) -> 5 | AM38: =ROUNDDOWN((AA38*0.1)+(AE38*0.2)+(AI38*0.4)+(AL38*0.3),1) -> #DIV/0! | AN38: =Midterms!AK38 -> #DIV/0! | AO38: =(AM38*0.5)+(AN38*0.5) -> #DIV/0!
A39: 34 | Y39: =SUM(S39:X39) -> 0 | Z39: =ROUNDUP(Y39*100/$Y$5,0) -> #DIV/0! | AA39: =VLOOKUP(Z39,Grading!$A$1:$B$102,2,TRUE) -> #DIV/0! | AC39: =SUM(AB39) -> 0 | AD39: =ROUNDUP(AC39*100/$AC$5,0) -> 0 | AE39: =VLOOKUP(AD39,Grading!$A$1:$B$102,2,TRUE) -> 5 | AG39: =SUM(AF39) -> 0 | AH39: =ROUNDUP(AG39*100/$AF$5,0) -> 0 | AI39: =VLOOKUP(AH39,Grading!$A$1:$B$102,2,TRUE) -> 5 | AK39: =ROUNDUP(AJ39*100/$AJ$5,0) -> 0 | AL39: =VLOOKUP(AK39,Grading!$A$1:$B$102,2,TRUE) -> 5 | AM39: =ROUNDDOWN((AA39*0.1)+(AE39*0.2)+(AI39*0.4)+(AL39*0.3),1) -> #DIV/0! | AN39: =Midterms!AK39 -> #DIV/0! | AO39: =(AM39*0.5)+(AN39*0.5) -> #DIV/0!
A40: 35 | Y40: =SUM(S40:X40) -> 0 | Z40: =ROUNDUP(Y40*100/$Y$5,0) -> #DIV/0! | AA40: =VLOOKUP(Z40,Grading!$A$1:$B$102,2,TRUE) -> #DIV/0! | AC40: =SUM(AB40) -> 0 | AD40: =ROUNDUP(AC40*100/$AC$5,0) -> 0 | AE40: =VLOOKUP(AD40,Grading!$A$1:$B$102,2,TRUE) -> 5 | AG40: =SUM(AF40) -> 0 | AH40: =ROUNDUP(AG40*100/$AF$5,0) -> 0 | AI40: =VLOOKUP(AH40,Grading!$A$1:$B$102,2,TRUE) -> 5 | AK40: =ROUNDUP(AJ40*100/$AJ$5,0) -> 0 | AL40: =VLOOKUP(AK40,Grading!$A$1:$B$102,2,TRUE) -> 5 | AM40: =ROUNDDOWN((AA40*0.1)+(AE40*0.2)+(AI40*0.4)+(AL40*0.3),1) -> #DIV/0! | AN40: =Midterms!AK40 -> #DIV/0! | AO40: =(AM40*0.5)+(AN40*0.5) -> #DIV/0!
A41: 36 | Y41: =SUM(S41:X41) -> 0 | Z41: =ROUNDUP(Y41*100/$Y$5,0) -> #DIV/0! | AA41: =VLOOKUP(Z41,Grading!$A$1:$B$102,2,TRUE) -> #DIV/0! | AC41: =SUM(AB41) -> 0 | AD41: =ROUNDUP(AC41*100/$AC$5,0) -> 0 | AE41: =VLOOKUP(AD41,Grading!$A$1:$B$102,2,TRUE) -> 5 | AG41: =SUM(AF41) -> 0 | AH41: =ROUNDUP(AG41*100/$AF$5,0) -> 0 | AI41: =VLOOKUP(AH41,Grading!$A$1:$B$102,2,TRUE) -> 5 | AK41: =ROUNDUP(AJ41*100/$AJ$5,0) -> 0 | AL41: =VLOOKUP(AK41,Grading!$A$1:$B$102,2,TRUE) -> 5 | AM41: =ROUNDDOWN((AA41*0.1)+(AE41*0.2)+(AI41*0.4)+(AL41*0.3),1) -> #DIV/0! | AN41: =Midterms!AK41 -> #DIV/0! | AO41: =(AM41*0.5)+(AN41*0.5) -> #DIV/0! | AP41: INC
...

Sheet Finals without PT
A1: [SUBJECT TITLE]
A2: STUDENTS | D2: Activities | L2: Quiz | R2: Final Exam | V2: Course Grade
I3: CA TOTAL | J3: % | K3: CA GRADE | O3: QUIZ TOTAL | P3: % | Q3: QUIZ GRADE | S3: % | T3: Final Exam Grade | U3: Finals Grade | V3: Midterm Grade | W3: Course Grade
A4: DATE
A5: TOTAL POINTS | I5: =SUM(D5:H5) -> 0 | J5: 100 | K5: #ERROR! | O5: =SUM(L5:N5) -> 0 | P5: =ROUNDUP(O5*100/$O$5,0) -> #DIV/0! | Q5: #ERROR! | S5: =ROUNDUP(R5*100/$R$5,0) -> #DIV/0! | T5: #ERROR! | U5: =ROUNDDOWN((K5*0.2)+(Q5*0.2)+(T5*0.6),1) -> #VALUE!
A6: 1 | I6: =SUM(D6:H6) -> 0 | J6: =ROUNDUP(I6*100/$I$5,0) -> #DIV/0! | K6: #ERROR! | O6: =SUM(L6:N6) -> 0 | P6: =ROUNDUP(O6*100/$O$5,0) -> #DIV/0! | Q6: #ERROR! | S6: =ROUNDUP(R6*100/$R$5,0) -> #DIV/0! | T6: #ERROR! | U6: =ROUNDDOWN((K6*0.2)+(Q6*0.2)+(T6*0.6),1) -> #VALUE! | W6: =(U6*0.5)+(V6*0.5) -> #VALUE!
A7: 2 | I7: =SUM(D7:H7) -> 0 | J7: =ROUNDUP(I7*100/$I$5,0) -> #DIV/0! | K7: #ERROR! | O7: =SUM(L7:N7) -> 0 | P7: =ROUNDUP(O7*100/$O$5,0) -> #DIV/0! | Q7: #ERROR! | S7: =ROUNDUP(R7*100/$R$5,0) -> #DIV/0! | T7: #ERROR! | U7: =ROUNDDOWN((K7*0.2)+(Q7*0.2)+(T7*0.6),1) -> #VALUE! | W7: =(U7*0.5)+(V7*0.5) -> #VALUE!
A8: 3 | I8: =SUM(D8:H8) -> 0 | J8: =ROUNDUP(I8*100/$I$5,0) -> #DIV/0! | K8: #ERROR! | O8: =SUM(L8:N8) -> 0 | P8: =ROUNDUP(O8*100/$O$5,0) -> #DIV/0! | Q8: #ERROR! | S8: =ROUNDUP(R8*100/$R$5,0) -> #DIV/0! | T8: #ERROR! | U8: =ROUNDDOWN((K8*0.2)+(Q8*0.2)+(T8*0.6),1) -> #VALUE! | W8: =(U8*0.5)+(V8*0.5) -> #VALUE!
A9: 4 | I9: =SUM(D9:H9) -> 0 | J9: =ROUNDUP(I9*100/$I$5,0) -> #DIV/0! | K9: #ERROR! | O9: =SUM(L9:N9) -> 0 | P9: =ROUNDUP(O9*100/$O$5,0) -> #DIV/0! | Q9: #ERROR! | S9: =ROUNDUP(R9*100/$R$5,0) -> #DIV/0! | T9: #ERROR! | U9: =ROUNDDOWN((K9*0.2)+(Q9*0.2)+(T9*0.6),1) -> #VALUE! | W9: =(U9*0.5)+(V9*0.5) -> #VALUE!
A10: 5 | I10: =SUM(D10:H10) -> 0 | J10: =ROUNDUP(I10*100/$I$5,0) -> #DIV/0! | K10: #ERROR! | O10: =SUM(L10:N10) -> 0 | P10: =ROUNDUP(O10*100/$O$5,0) -> #DIV/0! | Q10: #ERROR! | S10: =ROUNDUP(R10*100/$R$5,0) -> #DIV/0! | T10: #ERROR! | U10: =ROUNDDOWN((K10*0.2)+(Q10*0.2)+(T10*0.6),1) -> #VALUE! | W10: =(U10*0.5)+(V10*0.5) -> #VALUE!
A11: 6 | I11: =SUM(D11:H11) -> 0 | J11: =ROUNDUP(I11*100/$I$5,0) -> #DIV/0! | K11: #ERROR! | O11: =SUM(L11:N11) -> 0 | P11: =ROUNDUP(O11*100/$O$5,0) -> #DIV/0! | Q11: #ERROR! | S11: =ROUNDUP(R11*100/$R$5,0) -> #DIV/0! | T11: #ERROR! | U11: =ROUNDDOWN((K11*0.2)+(Q11*0.2)+(T11*0.6),1) -> #VALUE! | W11: =(U11*0.5)+(V11*0.5) -> #VALUE!
A12: 7 | I12: =SUM(D12:H12) -> 0 | J12: =ROUNDUP(I12*100/$I$5,0) -> #DIV/0! | K12: #ERROR! | O12: =SUM(L12:N12) -> 0 | P12: =ROUNDUP(O12*100/$O$5,0) -> #DIV/0! | Q12: #ERROR! | S12: =ROUNDUP(R12*100/$R$5,0) -> #DIV/0! | T12: #ERROR! | U12: =ROUNDDOWN((K12*0.2)+(Q12*0.2)+(T12*0.6),1) -> #VALUE! | W12: =(U12*0.5)+(V12*0.5) -> #VALUE!
A13: 8 | I13: =SUM(D13:H13) -> 0 | J13: =ROUNDUP(I13*100/$I$5,0) -> #DIV/0! | K13: #ERROR! | O13: =SUM(L13:N13) -> 0 | P13: =ROUNDUP(O13*100/$O$5,0) -> #DIV/0! | Q13: #ERROR! | S13: =ROUNDUP(R13*100/$R$5,0) -> #DIV/0! | T13: #ERROR! | U13: =ROUNDDOWN((K13*0.2)+(Q13*0.2)+(T13*0.6),1) -> #VALUE! | W13: =(U13*0.5)+(V13*0.5) -> #VALUE!
A14: 9 | I14: =SUM(D14:H14) -> 0 | J14: =ROUNDUP(I14*100/$I$5,0) -> #DIV/0! | K14: #ERROR! | O14: =SUM(L14:N14) -> 0 | P14: =ROUNDUP(O14*100/$O$5,0) -> #DIV/0! | Q14: #ERROR! | S14: =ROUNDUP(R14*100/$R$5,0) -> #DIV/0! | T14: #ERROR! | U14: =ROUNDDOWN((K14*0.2)+(Q14*0.2)+(T14*0.6),1) -> #VALUE! | W14: =(U14*0.5)+(V14*0.5) -> #VALUE!
A15: 10 | I15: =SUM(D15:H15) -> 0 | J15: =ROUNDUP(I15*100/$I$5,0) -> #DIV/0! | K15: #ERROR! | O15: =SUM(L15:N15) -> 0 | P15: =ROUNDUP(O15*100/$O$5,0) -> #DIV/0! | Q15: #ERROR! | S15: =ROUNDUP(R15*100/$R$5,0) -> #DIV/0! | T15: #ERROR! | U15: =ROUNDDOWN((K15*0.2)+(Q15*0.2)+(T15*0.6),1) -> #VALUE! | W15: =(U15*0.5)+(V15*0.5) -> #VALUE!
A16: 11 | I16: =SUM(D16:H16) -> 0 | J16: =ROUNDUP(I16*100/$I$5,0) -> #DIV/0! | K16: #ERROR! | O16: =SUM(L16:N16) -> 0 | P16: =ROUNDUP(O16*100/$O$5,0) -> #DIV/0! | Q16: #ERROR! | S16: =ROUNDUP(R16*100/$R$5,0) -> #DIV/0! | T16: #ERROR! | U16: =ROUNDDOWN((K16*0.2)+(Q16*0.2)+(T16*0.6),1) -> #VALUE! | W16: =(U16*0.5)+(V16*0.5) -> #VALUE!
A17: 12 | I17: =SUM(D17:H17) -> 0 | J17: =ROUNDUP(I17*100/$I$5,0) -> #DIV/0! | K17: #ERROR! | O17: =SUM(L17:N17) -> 0 | P17: =ROUNDUP(O17*100/$O$5,0) -> #DIV/0! | Q17: #ERROR! | S17: =ROUNDUP(R17*100/$R$5,0) -> #DIV/0! | T17: #ERROR! | U17: =ROUNDDOWN((K17*0.2)+(Q17*0.2)+(T17*0.6),1) -> #VALUE! | W17: =(U17*0.5)+(V17*0.5) -> #VALUE!
... A31: 26 | I31: =SUM(D31:H31) -> 0 | J31: =ROUNDUP(I31*100/$I$5,0) -> #DIV/0! | K31: #ERROR! | O31: =SUM(L31:N31) -> 0 | P31: =ROUNDUP(O31*100/$O$5,0) -> #DIV/0! | Q31: #ERROR! | S31: =ROUNDUP(R31*100/$R$5,0) -> #DIV/0! | T31: #ERROR! | U31: =ROUNDDOWN((K31*0.2)+(Q31*0.2)+(T31*0.6),1) -> #VALUE! | W31: =(U31*0.5)+(V31*0.5) -> #VALUE!
